Workbook

Sheet 18+ Shoppers
B1: 18+ Victoria Secret shoppers vs 18+ Other shopper
B2: Vividata's SCC | Study of the Canadian Consumer
D3: Women's Clothing-Where Personally Bought/Past 12 Months (National) | E3: Women's Clothing-Where Personally Bought/Past 12 Months (National)
D4: Victoria's Secret | E4: La Senza OR La Vie en Rose
B5: Base: 18+ | D5: 2025 Summer to 2023 Summer (Avg) | E5: 2025 Summer to 2023 Summer (Avg)
B6: Totals | C6: Pop. (000) | D6: =AVERAGE('Full dates'!D6:L6) -> 1004.4444 | E6: =AVERAGE('Full dates'!M6:U6) -> 1948.2222
C7: % Col | D7: =AVERAGE('Full dates'!D7:L7) -> 100 | E7: =AVERAGE('Full dates'!M7:U7) -> 100
A8: Personal Appearance-Statements-Any Agree (4-5) | B8: My confidence is greatly enhanced when I know I look my best | C8: Pop. (000) | D8: =AVERAGE('Full dates'!D8:L8) -> 644.11111 | E8: =AVERAGE('Full dates'!M8:U8) -> 1289
C9: % Col | D9: =AVERAGE('Full dates'!D9:L9) -> 64.57 | E9: =AVERAGE('Full dates'!M9:U9) -> 66.74
A10: Personal Appearance-Statements-Any Disagree (1-2) | B10: My confidence is greatly enhanced when I know I look my best | C10: Pop. (000) | D10: =AVERAGE('Full dates'!D10:L10) -> 89.555556 | E10: =AVERAGE('Full dates'!M10:U10) -> 199.77778
C11: % Col | D11: =AVERAGE('Full dates'!D11:L11) -> 8.7344444 | E11: =AVERAGE('Full dates'!M11:U11) -> 10.016667
A12: Social/Political/Ethical-Statements-Any Agree (4-5) | B12: I think we should strive for equality for all | C12: Pop. (000) | D12: =AVERAGE('Full dates'!D12:L12) -> 732.66667 | E12: =AVERAGE('Full dates'!M12:U12) -> 1459
C13: % Col | D13: =AVERAGE('Full dates'!D13:L13) -> 73.05889 | E13: =AVERAGE('Full dates'!M13:U13) -> 75.061111
A14: Social/Political/Ethical-Statements-Any Agree (4-5) | B14: Men and women should share household responsibilities equally | C14: Pop. (000) | D14: =AVERAGE('Full dates'!D14:L14) -> 730.88889 | E14: =AVERAGE('Full dates'!M14:U14) -> 1462.3333
C15: % Col | D15: =AVERAGE('Full dates'!D15:L15) -> 72.599999 | E15: =AVERAGE('Full dates'!M15:U15) -> 75.073334
A16: Social/Political/Ethical-Statements-Any Agree (4-5) | B16: I think men and women are given equal opportunities | C16: Pop. (000) | D16: =AVERAGE('Full dates'!D16:L16) -> 391.44444 | E16: =AVERAGE('Full dates'!M16:U16) -> 736.33333
C17: % Col | D17: =AVERAGE('Full dates'!D17:L17) -> 38.892223 | E17: =AVERAGE('Full dates'!M17:U17) -> 37.613333
A18: Social/Political/Ethical-Statements-Any Agree (4-5) | B18: Men and women are still not treated equally in the workplace | C18: Pop. (000) | D18: =AVERAGE('Full dates'!D18:L18) -> 635 | E18: =AVERAGE('Full dates'!M18:U18) -> 1250.5556
C19: % Col | D19: =AVERAGE('Full dates'!D19:L19) -> 63.513333 | E19: =AVERAGE('Full dates'!M19:U19) -> 64.253333
A20: Social/Political/Ethical-Statements-Any Agree (4-5) | B20: Feminism isn’t about treating women favourably but equally | C20: Pop. (000) | D20: =AVERAGE('Full dates'!D20:L20) -> 688.11111 | E20: =AVERAGE('Full dates'!M20:U20) -> 1330.1111
C21: % Col | D21: =AVERAGE('Full dates'!D21:L21) -> 68.565556 | E21: =AVERAGE('Full dates'!M21:U21) -> 68.247777
A22: Social/Political/Ethical-Statements-Any Disagree (1-2) | B22: I think we should strive for equality for all | C22: Pop. (000) | D22: =AVERAGE('Full dates'!D22:L22) -> 38 | E22: =AVERAGE('Full dates'!M22:U22) -> 91.666667
C23: % Col | D23: =AVERAGE('Full dates'!D23:L23) -> 3.6788889 | E23: =AVERAGE('Full dates'!M23:U23) -> 4.6955555
A24: Social/Political/Ethical-Statements-Any Disagree (1-2) | B24: Men and women should share household responsibilities equally | C24: Pop. (000) | D24: =AVERAGE('Full dates'!D24:L24) -> 55 | E24: =AVERAGE('Full dates'!M24:U24) -> 100.11111
C25: % Col | D25: =AVERAGE('Full dates'!D25:L25) -> 5.4866667 | E25: =AVERAGE('Full dates'!M25:U25) -> 5.1333334
A26: Social/Political/Ethical-Statements-Any Disagree (1-2) | B26: I think men and women are given equal opportunities | C26: Pop. (000) | D26: =AVERAGE('Full dates'!D26:L26) -> 299.11111 | E26: =AVERAGE('Full dates'!M26:U26) -> 621.77778
C27: % Col | D27: =AVERAGE('Full dates'!D27:L27) -> 29.79 | E27: =AVERAGE('Full dates'!M27:U27) -> 31.893333
A28: Social/Political/Ethical-Statements-Any Disagree (1-2) | B28: Men and women are still not treated equally in the workplace | C28: Pop. (000) | D28: =AVERAGE('Full dates'!D28:L28) -> 101.88889 | E28: =AVERAGE('Full dates'!M28:U28) -> 210.77778
C29: % Col | D29: =AVERAGE('Full dates'!D29:L29) -> 10.034444 | E29: =AVERAGE('Full dates'!M29:U29) -> 10.751111
A30: Social/Political/Ethical-Statements-Any Disagree (1-2) | B30: Feminism isn’t about treating women favourably but equally | C30: Pop. (000) | D30: =AVERAGE('Full dates'!D30:L30) -> 69.777778 | E30: =AVERAGE('Full dates'!M30:U30) -> 139.44444
C31: % Col | D31: =AVERAGE('Full dates'!D31:L31) -> 6.7411111 | E31: =AVERAGE('Full dates'!M31:U31) -> 7.0833334
A32: Geography-Province | B32: Nova Scotia | C32: Pop. (000) | D32: =AVERAGE('Full dates'!D36:L36) -> 24.714286 | E32: =AVERAGE('Full dates'!M36:U36) -> 56.666667
C33: % Col | D33: =AVERAGE('Full dates'!D37:L37) -> 2.4 | E33: =AVERAGE('Full dates'!M37:U37) -> 2.9133333
A34: Geography-Province | B34: New Brunswick | C34: Pop. (000) | D34: =AVERAGE('Full dates'!D38:L38) -> 28 | E34: =AVERAGE('Full dates'!M38:U38) -> 40.333333
C35: % Col | D35: =AVERAGE('Full dates'!D39:L39) -> 1.45 | E35: =AVERAGE('Full dates'!M39:U39) -> 2.17
A36: Geography-Province | B36: Quebec | C36: Pop. (000) | D36: =AVERAGE('Full dates'!D40:L40) -> 151.88889 | E36: =AVERAGE('Full dates'!M40:U40) -> 540.55556
C37: % Col | D37: =AVERAGE('Full dates'!D41:L41) -> 15.243333 | E37: =AVERAGE('Full dates'!M41:U41) -> 28.054444
A38: Geography-Province | B38: Ontario | C38: Pop. (000) | D38: =AVERAGE('Full dates'!D42:L42) -> 454.22222 | E38: =AVERAGE('Full dates'!M42:U42) -> 694.11111
C39: % Col | D39: =AVERAGE('Full dates'!D43:L43) -> 45.253334 | E39: =AVERAGE('Full dates'!M43:U43) -> 35.449999
A40: Geography-Province | B40: Manitoba | C40: Pop. (000) | D40: =AVERAGE('Full dates'!D44:L44) -> 47 | E40: =AVERAGE('Full dates'!M44:U44) -> 68.428571
...

Sheet Full dates
B1: 18+ Victoria Secret shoppers vs 18+ Other shopper_Duplicate
B2: Vividata's SCC | Study of the Canadian Consumer
D3: Women's Clothing-Where Personally Bought/Past 12 Months (National) | M3: Women's Clothing-Where Personally Bought/Past 12 Months (National)
D4: Victoria's Secret | M4: La Senza OR La Vie en Rose
B5: Base: 18+ | D5: 2025 Summer | E5: 2025 Spring | F5: 2025 Winter | G5: 2024 Fall | H5: 2024 Summer | I5: 2024 Spring | J5: 2024 Winter | K5: 2023 Fall | L5: 2023 Summer | M5: 2025 Summer | N5: 2025 Spring | O5: 2025 Winter | P5: 2024 Fall | Q5: 2024 Summer | R5: 2024 Spring | S5: 2024 Winter | T5: 2023 Fall | U5: 2023 Summer
B6: Totals | C6: Pop. (000) | D6: 919 | E6: 906 | F6: 863 | G6: 883 | H6: 1282 | I6: 1109 | J6: 1101 | K6: 1014 | L6: 963 | M6: 1712 | N6: 1669 | O6: 1642 | P6: 1639 | Q6: 2440 | R6: 1979 | S6: 2171 | T6: 2214 | U6: 2068
C7: % Col | D7: 100 | E7: 100 | F7: 100 | G7: 100 | H7: 100 | I7: 100 | J7: 100 | K7: 100 | L7: 100 | M7: 100 | N7: 100 | O7: 100 | P7: 100 | Q7: 100 | R7: 100 | S7: 100 | T7: 100 | U7: 100
A8: Personal Appearance-Statements-Any Agree (4-5) | B8: My confidence is greatly enhanced when I know I look my best | C8: Pop. (000) | D8: 634 | E8: 632 | F8: 595 | G8: 585 | H8: 740 | I8: 691 | J8: 694 | K8: 612 | L8: 614 | M8: 1229 | N8: 1199 | O8: 1168 | P8: 1160 | Q8: 1469 | R8: 1221 | S8: 1381 | T8: 1417 | U8: 1357
C9: % Col | D9: 68.989998 | E9: 69.760002 | F9: 68.949997 | G9: 66.25 | H9: 57.720001 | I9: 62.310001 | J9: 63.029999 | K9: 60.360001 | L9: 63.759998 | M9: 71.790001 | N9: 71.839996 | O9: 71.129997 | P9: 70.769997 | Q9: 60.200001 | R9: 61.700001 | S9: 63.610001 | T9: 64 | U9: 65.620003
A10: Personal Appearance-Statements-Any Disagree (1-2) | B10: My confidence is greatly enhanced when I know I look my best | C10: Pop. (000) | D10: 75 | E10: 75 | F10: 72 | G10: 70 | H10: 191 | I10: 78 | J10: 83 | K10: 75 | L10: 87 | M10: 135 | N10: 139 | O10: 148 | P10: 132 | Q10: 327 | R10: 214 | S10: 246 | T10: 242 | U10: 215
C11: % Col | D11: 8.1599998 | E11: 8.2799997 | F11: 8.3400002 | G11: 7.9299998 | H11: 14.9 | I11: 7.0300002 | J11: 7.54 | K11: 7.4000001 | L11: 9.0299997 | M11: 7.8899999 | N11: 8.3299999 | O11: 9.0100002 | P11: 8.0500002 | Q11: 13.4 | R11: 10.81 | S11: 11.33 | T11: 10.93 | U11: 10.4
A12: Social/Political/Ethical-Statements-Any Agree (4-5) | B12: I think we should strive for equality for all | C12: Pop. (000) | D12: 674 | E12: 662 | F12: 619 | G12: 646 | H12: 881 | I12: 806 | J12: 828 | K12: 736 | L12: 742 | M12: 1295 | N12: 1274 | O12: 1250 | P12: 1267 | Q12: 1773 | R12: 1448 | S12: 1629 | T12: 1632 | U12: 1563
C13: % Col | D13: 73.339996 | E13: 73.07 | F13: 71.730003 | G13: 73.160004 | H13: 68.720001 | I13: 72.68 | J13: 75.199997 | K13: 72.580002 | L13: 77.050003 | M13: 75.639999 | N13: 76.330002 | O13: 76.129997 | P13: 77.300003 | Q13: 72.660004 | R13: 73.169998 | S13: 75.029999 | T13: 73.709999 | U13: 75.580002
A14: Social/Political/Ethical-Statements-Any Agree (4-5) | B14: Men and women should share household responsibilities equally | C14: Pop. (000) | D14: 663 | E14: 645 | F14: 613 | G14: 625 | H14: 958 | I14: 832 | J14: 802 | K14: 741 | L14: 699 | M14: 1282 | N14: 1251 | O14: 1237 | P14: 1256 | Q14: 1873 | R14: 1471 | S14: 1618 | T14: 1629 | U14: 1544
C15: % Col | D15: 72.139999 | E15: 71.190002 | F15: 71.029999 | G15: 70.779999 | H15: 74.730003 | I15: 75.019997 | J15: 72.839996 | K15: 73.080002 | L15: 72.589996 | M15: 74.879997 | N15: 74.959999 | O15: 75.330002 | P15: 76.629997 | Q15: 76.760002 | R15: 74.330002 | S15: 74.529999 | T15: 73.580002 | U15: 74.660004
A16: Social/Political/Ethical-Statements-Any Agree (4-5) | B16: I think men and women are given equal opportunities | C16: Pop. (000) | D16: 363 | E16: 365 | F16: 336 | G16: 349 | H16: 549 | I16: 427 | J16: 409 | K16: 375 | L16: 350 | M16: 595 | N16: 600 | O16: 604 | P16: 604 | Q16: 968 | R16: 792 | S16: 841 | T16: 854 | U16: 769
C17: % Col | D17: 39.5 | E17: 40.290001 | F17: 38.93 | G17: 39.52 | H17: 42.82 | I17: 38.5 | J17: 37.150002 | K17: 36.98 | L17: 36.34 | M17: 34.75 | N17: 35.950001 | O17: 36.779999 | P17: 36.849998 | Q17: 39.669998 | R17: 40.02 | S17: 38.740002 | T17: 38.57 | U17: 37.189999
A18: Social/Political/Ethical-Statements-Any Agree (4-5) | B18: Men and women are still not treated equally in the workplace | C18: Pop. (000) | D18: 616 | E18: 595 | F18: 561 | G18: 573 | H18: 737 | I18: 702 | J18: 687 | K18: 641 | L18: 603 | M18: 1124 | N18: 1064 | O18: 1051 | P18: 1078 | Q18: 1570 | R18: 1276 | S18: 1384 | T18: 1386 | U18: 1322
C19: % Col | D19: 67.029999 | E19: 65.669998 | F19: 65.010002 | G19: 64.889999 | H19: 57.490002 | I19: 63.299999 | J19: 62.400002 | K19: 63.209999 | L19: 62.619999 | M19: 65.650002 | N19: 63.75 | O19: 64.010002 | P19: 65.769997 | Q19: 64.339996 | R19: 64.480003 | S19: 63.75 | T19: 62.599998 | U19: 63.93
A20: Social/Political/Ethical-Statements-Any Agree (4-5) | B20: Feminism isn’t about treating women favourably but equally | C20: Pop. (000) | D20: 623 | E20: 613 | F20: 566 | G20: 589 | H20: 798 | I20: 800 | J20: 778 | K20: 724 | L20: 702 | M20: 1179 | N20: 1128 | O20: 1096 | P20: 1098 | Q20: 1609 | R20: 1371 | S20: 1498 | T20: 1527 | U20: 1465
C21: % Col | D21: 67.790001 | E21: 67.660004 | F21: 65.589996 | G21: 66.699997 | H21: 62.25 | I21: 72.139999 | J21: 70.660004 | K21: 71.400002 | L21: 72.900002 | M21: 68.870003 | N21: 67.589996 | O21: 66.75 | P21: 66.989998 | Q21: 65.940002 | R21: 69.279999 | S21: 69 | T21: 68.970001 | U21: 70.839996
A22: Social/Political/Ethical-Statements-Any Disagree (1-2) | B22: I think we should strive for equality for all | C22: Pop. (000) | D22: 28 | E22: 29 | F22: 32 | G22: 33 | H22: 89 | I22: 40 | J22: 33 | K22: 31 | L22: 27 | M22: 79 | N22: 83 | O22: 80 | P22: 72 | Q22: 119 | R22: 71 | S22: 84 | T22: 121 | U22: 116
C23: % Col | D23: 3.05 | E23: 3.2 | F23: 3.71 | G23: 3.74 | H23: 6.9400001 | I23: 3.6099999 | J23: 3 | K23: 3.0599999 | L23: 2.8 | M23: 4.6100001 | N23: 4.9699998 | O23: 4.8699999 | P23: 4.3899999 | Q23: 4.8800001 | R23: 3.5899999 | S23: 3.8699999 | T23: 5.4699998 | U23: 5.6100001
A24: Social/Political/Ethical-Statements-Any Disagree (1-2) | B24: Men and women should share household responsibilities equally | C24: Pop. (000) | D24: 50 | E24: 51 | F24: 50 | G24: 47 | H24: 58 | I24: 68 | J24: 70 | K24: 57 | L24: 44 | M24: 90 | N24: 88 | O24: 89 | P24: 74 | Q24: 123 | R24: 110 | S24: 109 | T24: 132 | U24: 86
C25: % Col | D25: 5.4400001 | E25: 5.6300001 | F25: 5.79 | G25: 5.3200002 | H25: 4.52 | I25: 6.1300001 | J25: 6.3600001 | K25: 5.6199999 | L25: 4.5700002 | M25: 5.2600002 | N25: 5.27 | O25: 5.4200001 | P25: 4.5100002 | Q25: 5.04 | R25: 5.5599999 | S25: 5.02 | T25: 5.96 | U25: 4.1599998
A26: Social/Political/Ethical-Statements-Any Disagree (1-2) | B26: I think men and women are given equal opportunities | C26: Pop. (000) | D26: 275 | E26: 264 | F26: 254 | G26: 265 | H26: 377 | I26: 332 | J26: 331 | K26: 284 | L26: 310 | M26: 559 | N26: 520 | O26: 501 | P26: 522 | Q26: 748 | R26: 605 | S26: 673 | T26: 737 | U26: 731
C27: % Col | D27: 29.92 | E27: 29.139999 | F27: 29.43 | G27: 30.01 | H27: 29.41 | I27: 29.940001 | J27: 30.059999 | K27: 28.01 | L27: 32.189999 | M27: 32.650002 | N27: 31.16 | O27: 30.51 | P27: 31.85 | Q27: 30.66 | R27: 30.57 | S27: 31 | T27: 33.290001 | U27: 35.349998
A28: Social/Political/Ethical-Statements-Any Disagree (1-2) | B28: Men and women are still not treated equally in the workplace | C28: Pop. (000) | D28: 87 | E28: 91 | F28: 78 | G28: 83 | H28: 159 | I28: 115 | J28: 117 | K28: 89 | L28: 98 | M28: 180 | N28: 192 | O28: 173 | P28: 150 | Q28: 300 | R28: 196 | S28: 209 | T28: 252 | U28: 245
C29: % Col | D29: 9.4700003 | E29: 10.04 | F29: 9.04 | G29: 9.3999996 | H29: 12.4 | I29: 10.37 | J29: 10.63 | K29: 8.7799997 | L29: 10.18 | M29: 10.51 | N29: 11.5 | O29: 10.54 | P29: 9.1499996 | Q29: 12.3 | R29: 9.8999996 | S29: 9.6300001 | T29: 11.38 | U29: 11.85
A30: Social/Political/Ethical-Statements-Any Disagree (1-2) | B30: Feminism isn’t about treating women favourably but equally | C30: Pop. (000) | D30: 44 | E30: 44 | F30: 46 | G30: 53 | H30: 132 | I30: 89 | J30: 87 | K30: 68 | L30: 65 | M30: 117 | N30: 121 | O30: 113 | P30: 109 | Q30: 224 | R30: 121 | S30: 144 | T30: 182 | U30: 124
C31: % Col | D31: 4.79 | E31: 4.8600001 | F31: 5.3299999 | G31: 6 | H31: 10.3 | I31: 8.0299997 | J31: 7.9000001 | K31: 6.71 | L31: 6.75 | M31: 6.8299999 | N31: 7.25 | O31: 6.8800001 | P31: 6.6500001 | Q31: 9.1800003 | R31: 6.1100001 | S31: 6.6300001 | T31: 8.2200003 | U31: 6
A32: Geography-Province | B32: Newfoundland and Labrador | C32: Pop. (000) | D32: 2 # | E32: 0 # | F32: 0 # | G32: 0 # | H32: 8 # | I32: 5 # | J32: 4 # | K32: 4 # | L32: 6 # | M32: 21 * | N32: 19 * | O32: 12 * | P32: 10 * | Q32: 45 | R32: 38 | S32: 39 | T32: 38 | U32: 46
C33: % Col | D33: 0.22 | E33: 0 | F33: 0 | G33: 0 | H33: 0.62 | I33: 0.44999999 | J33: 0.36000001 | K33: 0.38999999 | L33: 0.62 | M33: 1.23 | N33: 1.14 | O33: 0.73000002 | P33: 0.61000001 | Q33: 1.84 | R33: 1.92 | S33: 1.8 | T33: 1.72 | U33: 2.22
A34: Geography-Province | B34: Prince Edward Island | C34: Pop. (000) | D34: 4 # | E34: 2 # | F34: 4 # | G34: 4 # | H34: 4 # | I34: 5 # | J34: 3 # | K34: 4 # | L34: 3 # | M34: 10 # | N34: 8 # | O34: 6 # | P34: 7 # | Q34: 13 # | R34: 8 * | S34: 8 # | T34: 9 * | U34: 8 #
C35: % Col | D35: 0.44 | E35: 0.22 | F35: 0.46000001 | G35: 0.44999999 | H35: 0.31 | I35: 0.44999999 | J35: 0.27000001 | K35: 0.38999999 | L35: 0.31 | M35: 0.57999998 | N35: 0.47999999 | O35: 0.37 | P35: 0.43000001 | Q35: 0.52999997 | R35: 0.40000001 | S35: 0.37 | T35: 0.41 | U35: 0.38999999
A36: Geography-Province | B36: Nova Scotia | C36: Pop. (000) | D36: 21 | E36: 24 | F36: 26 | G36: 25 | H36: 17 * | I36: 26 | J36: 22 * | K36: 28 | L36: 23 | M36: 52 | N36: 49 | O36: 50 | P36: 44 | Q36: 64 | R36: 57 | S36: 72 | T36: 67 | U36: 55
C37: % Col | D37: 2.29 | E37: 2.6500001 | F37: 3.01 | G37: 2.8299999 | H37: 1.33 | I37: 2.3399999 | J37: 2 | K37: 2.76 | L37: 2.3900001 | M37: 3.04 | N37: 2.9400001 | O37: 3.05 | P37: 2.6800001 | Q37: 2.6199999 | R37: 2.8800001 | S37: 3.3199999 | T37: 3.03 | U37: 2.6600001
A38: Geography-Province | B38: New Brunswick | C38: Pop. (000) | D38: 5 * | E38: 5 # | F38: 6 # | G38: 10 # | H38: 15 * | I38: 28 | J38: 21 * | K38: 27 * | L38: 18 * | M38: 50 | N38: 52 | O38: 51 | P38: 50 | Q38: 41 | R38: 24 | S38: 28 | T38: 26 | U38: 41
C39: % Col | D39: 0.54000002 | E39: 0.55000001 | F39: 0.69999999 | G39: 1.13 | H39: 1.17 | I39: 2.52 | J39: 1.91 | K39: 2.6600001 | L39: 1.87 | M39: 2.9200001 | N39: 3.1199999 | O39: 3.1099999 | P39: 3.05 | Q39: 1.6799999 | R39: 1.21 | S39: 1.29 | T39: 1.17 | U39: 1.98
A40: Geography-Province | B40: Quebec | C40: Pop. (000) | D40: 142 | E40: 143 | F40: 134 | G40: 133 | H40: 153 | I40: 141 | J40: 190 | K40: 171 | L40: 160 | M40: 514 | N40: 491 | O40: 517 | P40: 541 | Q40: 700 | R40: 571 | S40: 581 | T40: 530 | U40: 420
...
